2023-02-25 19:57:54,992 INFO    StreamThr :19608 [internal.py:wandb_internal():87] W&B internal server running at pid: 19608, started at: 2023-02-25 19:57:54.992819
2023-02-25 19:57:54,994 DEBUG   HandlerThread:19608 [handler.py:handle_request():144] handle_request: status
2023-02-25 19:57:54,995 INFO    WriterThread:19608 [datastore.py:open_for_write():85] open: C:\Users\anant\CS6910\Assignment 1\wandb\run-20230225_195749-ptf2nm3b\run-ptf2nm3b.wandb
2023-02-25 19:57:54,997 DEBUG   SenderThread:19608 [sender.py:send():336] send: header
2023-02-25 19:57:55,005 DEBUG   SenderThread:19608 [sender.py:send():336] send: run
2023-02-25 19:57:55,585 ERROR   SenderThread:19608 [internal_api.py:execute():245] 404 response executing GraphQL.
2023-02-25 19:57:55,585 ERROR   SenderThread:19608 [internal_api.py:execute():246] {"errors":[{"message":"entity Ananthakrishnan A not found during upsertBucket","path":["upsertBucket"]}],"data":{"upsertBucket":null}}
2023-02-25 19:57:56,016 INFO    HandlerThread:19608 [handler.py:finish():841] shutting down handler
2023-02-25 19:57:56,016 INFO    WriterThread:19608 [datastore.py:close():299] close: C:\Users\anant\CS6910\Assignment 1\wandb\run-20230225_195749-ptf2nm3b\run-ptf2nm3b.wandb
2023-02-25 19:57:56,016 ERROR   StreamThr :19608 [internal.py:wandb_internal():175] Thread SenderThread:
Traceback (most recent call last):
  File "C:\Users\anant\anaconda3\lib\site-packages\wandb\sdk\lib\retry.py", line 131, in __call__
    result = self._call_fn(*args, **kwargs)
  File "C:\Users\anant\anaconda3\lib\site-packages\wandb\sdk\internal\internal_api.py", line 242, in execute
    return self.client.execute(*args, **kwargs)  # type: ignore
  File "C:\Users\anant\anaconda3\lib\site-packages\wandb\vendor\gql-0.2.0\wandb_gql\client.py", line 52, in execute
    result = self._get_result(document, *args, **kwargs)
  File "C:\Users\anant\anaconda3\lib\site-packages\wandb\vendor\gql-0.2.0\wandb_gql\client.py", line 60, in _get_result
    return self.transport.execute(document, *args, **kwargs)
  File "C:\Users\anant\anaconda3\lib\site-packages\wandb\vendor\gql-0.2.0\wandb_gql\transport\requests.py", line 39, in execute
    request.raise_for_status()
  File "C:\Users\anant\anaconda3\lib\site-packages\requests\models.py", line 1021, in raise_for_status
    raise HTTPError(http_error_msg, response=self)
requests.exceptions.HTTPError: 404 Client Error: Not Found for url: https://api.wandb.ai/graphql

During handling of the above exception, another exception occurred:

Traceback (most recent call last):
  File "C:\Users\anant\anaconda3\lib\site-packages\wandb\apis\normalize.py", line 26, in wrapper
    return func(*args, **kwargs)
  File "C:\Users\anant\anaconda3\lib\site-packages\wandb\sdk\internal\internal_api.py", line 1593, in upsert_run
    response = self.gql(
  File "C:\Users\anant\anaconda3\lib\site-packages\wandb\sdk\internal\internal_api.py", line 214, in gql
    ret = self._retry_gql(
  File "C:\Users\anant\anaconda3\lib\site-packages\wandb\sdk\lib\retry.py", line 147, in __call__
    retry_timedelta_triggered = check_retry_fn(e)
  File "C:\Users\anant\anaconda3\lib\site-packages\wandb\util.py", line 1066, in check_retry_fn
    return fallback_retry_fn(e)
  File "C:\Users\anant\anaconda3\lib\site-packages\wandb\util.py", line 1013, in no_retry_auth
    raise CommError("Permission denied, ask the project owner to grant you access")
wandb.errors.CommError: Permission denied, ask the project owner to grant you access

During handling of the above exception, another exception occurred:

Traceback (most recent call last):
  File "C:\Users\anant\anaconda3\lib\site-packages\wandb\sdk\internal\internal_util.py", line 49, in run
    self._run()
  File "C:\Users\anant\anaconda3\lib\site-packages\wandb\sdk\internal\internal_util.py", line 100, in _run
    self._process(record)
  File "C:\Users\anant\anaconda3\lib\site-packages\wandb\sdk\internal\internal.py", line 329, in _process
    self._sm.send(record)
  File "C:\Users\anant\anaconda3\lib\site-packages\wandb\sdk\internal\sender.py", line 343, in send
    send_handler(record)
  File "C:\Users\anant\anaconda3\lib\site-packages\wandb\sdk\internal\sender.py", line 929, in send_run
    self._init_run(run, config_value_dict)
  File "C:\Users\anant\anaconda3\lib\site-packages\wandb\sdk\internal\sender.py", line 957, in _init_run
    server_run, inserted, server_messages = self._api.upsert_run(
  File "C:\Users\anant\anaconda3\lib\site-packages\wandb\apis\normalize.py", line 64, in wrapper
    raise CommError(message, err).with_traceback(sys.exc_info()[2])
  File "C:\Users\anant\anaconda3\lib\site-packages\wandb\apis\normalize.py", line 26, in wrapper
    return func(*args, **kwargs)
  File "C:\Users\anant\anaconda3\lib\site-packages\wandb\sdk\internal\internal_api.py", line 1593, in upsert_run
    response = self.gql(
  File "C:\Users\anant\anaconda3\lib\site-packages\wandb\sdk\internal\internal_api.py", line 214, in gql
    ret = self._retry_gql(
  File "C:\Users\anant\anaconda3\lib\site-packages\wandb\sdk\lib\retry.py", line 147, in __call__
    retry_timedelta_triggered = check_retry_fn(e)
  File "C:\Users\anant\anaconda3\lib\site-packages\wandb\util.py", line 1066, in check_retry_fn
    return fallback_retry_fn(e)
  File "C:\Users\anant\anaconda3\lib\site-packages\wandb\util.py", line 1013, in no_retry_auth
    raise CommError("Permission denied, ask the project owner to grant you access")
wandb.errors.CommError: Permission denied, ask the project owner to grant you access
