2023-03-04 01:58:23,806 INFO    Thread-432:16248 [wandb_setup.py:_flush():68] Configure stats pid to 16248
2023-03-04 01:58:23,806 INFO    Thread-432:16248 [wandb_setup.py:_flush():68] Loading settings from C:\Users\anant\.config\wandb\settings
2023-03-04 01:58:23,806 INFO    Thread-432:16248 [wandb_setup.py:_flush():68] Loading settings from C:\Users\anant\CS6910\Assignment 1\wandb\settings
2023-03-04 01:58:23,806 INFO    Thread-432:16248 [wandb_setup.py:_flush():68] Loading settings from environment variables: {'_require_service': 'True', 'project': 'CS6910_DL_ASS1', 'entity': 'ananthu2014', 'root_dir': 'C:\\Users\\anant\\CS6910\\Assignment 1', 'run_id': 'n8ym820q', 'sweep_param_path': 'C:\\Users\\anant\\CS6910\\Assignment 1\\wandb\\sweep-htulb8bc\\config-n8ym820q.yaml', 'sweep_id': 'htulb8bc'}
2023-03-04 01:58:23,824 INFO    Thread-432:16248 [wandb_setup.py:_flush():68] Inferring run settings from compute environment: {'program': '<python with no main file>'}
2023-03-04 01:58:23,824 INFO    Thread-432:16248 [wandb_init.py:_log_setup():492] Logging user logs to C:\Users\anant\CS6910\Assignment 1\wandb\run-20230304_015823-n8ym820q\logs\debug.log
2023-03-04 01:58:23,824 INFO    Thread-432:16248 [wandb_init.py:_log_setup():493] Logging internal logs to C:\Users\anant\CS6910\Assignment 1\wandb\run-20230304_015823-n8ym820q\logs\debug-internal.log
2023-03-04 01:58:23,824 INFO    Thread-432:16248 [wandb_init.py:_jupyter_setup():438] configuring jupyter hooks <wandb.sdk.wandb_init._WandbInit object at 0x000001611F2826A0>
2023-03-04 01:58:23,824 INFO    Thread-432:16248 [wandb_init.py:init():532] calling init triggers
2023-03-04 01:58:23,824 INFO    Thread-432:16248 [wandb_init.py:init():538] wandb.init called with sweep_config: {'activation': 'sigmoid_function', 'batch_size': 64, 'beta': 0.9, 'beta1': 0.9, 'beta2': 0.99, 'epochs': 20, 'lambd': 0, 'learning_rate': 0.1, 'loss': 'cross_entropy_function', 'momentum': 0.9, 'neurons': 128, 'num_hidden_layers': 1, 'optimizer': 'stochastic_gradient_descent', 'weight_init': 'random_initialization'}
config: {'learning_rate': 0.1, 'activation': 'sigmoid_function', 'weight_init': 'random_initialization', 'optimizer': 'stochastic_gradient_descent', 'batch_size': 4, 'epochs': 10, 'lambd': 0, 'neurons': 4, 'num_hidden_layers': 1, 'momentum': 0.5, 'beta': 0.5, 'beta1': 0.5, 'beta2': 0.5, 'loss': 'cross_entropy_function'}
2023-03-04 01:58:23,824 INFO    Thread-432:16248 [wandb_init.py:init():588] starting backend
2023-03-04 01:58:23,824 INFO    Thread-432:16248 [wandb_init.py:init():592] setting up manager
2023-03-04 01:58:23,824 INFO    Thread-432:16248 [backend.py:_multiprocessing_setup():106] multiprocessing start_methods=spawn, using: spawn
2023-03-04 01:58:23,838 INFO    Thread-432:16248 [wandb_init.py:init():599] backend started and connected
2023-03-04 01:58:23,871 INFO    Thread-432:16248 [wandb_run.py:_config_callback():1250] config_cb None None {'activation': 'sigmoid_function', 'batch_size': 64, 'beta': 0.9, 'beta1': 0.9, 'beta2': 0.99, 'epochs': 20, 'lambd': 0, 'learning_rate': 0.1, 'loss': 'cross_entropy_function', 'momentum': 0.9, 'neurons': 128, 'num_hidden_layers': 1, 'optimizer': 'stochastic_gradient_descent', 'weight_init': 'random_initialization'}
2023-03-04 01:58:23,871 INFO    Thread-432:16248 [wandb_run.py:_label_probe_notebook():1203] probe notebook
2023-03-04 01:58:23,871 INFO    Thread-432:16248 [wandb_run.py:_label_probe_notebook():1213] Unable to probe notebook: 'NoneType' object has no attribute 'get'
2023-03-04 01:58:23,871 INFO    Thread-432:16248 [wandb_init.py:init():687] updated telemetry
2023-03-04 01:58:23,947 INFO    Thread-432:16248 [wandb_init.py:init():727] communicating run to backend with 60.0 second timeout
2023-03-04 01:58:24,637 INFO    Thread-432:16248 [wandb_run.py:_on_init():2134] communicating current version
2023-03-04 01:58:24,700 INFO    Thread-432:16248 [wandb_run.py:_on_init():2143] got version response 
2023-03-04 01:58:24,700 INFO    Thread-432:16248 [wandb_init.py:init():775] starting run threads in backend
2023-03-04 01:58:46,359 INFO    Thread-432:16248 [wandb_run.py:_console_start():2114] atexit reg
2023-03-04 01:58:46,360 INFO    Thread-432:16248 [wandb_run.py:_redirect():1969] redirect: SettingsConsole.WRAP_RAW
2023-03-04 01:58:46,360 INFO    Thread-432:16248 [wandb_run.py:_redirect():2034] Wrapping output streams.
2023-03-04 01:58:46,360 INFO    Thread-432:16248 [wandb_run.py:_redirect():2059] Redirects installed.
2023-03-04 01:58:46,360 INFO    Thread-432:16248 [wandb_init.py:init():817] run started, returning control to user process
2023-03-04 09:25:23,247 INFO    Thread-9  :16248 [retry.py:__call__():172] Retry attempt failed:
Traceback (most recent call last):
  File "C:\Users\anant\anaconda3\lib\site-packages\urllib3\connection.py", line 174, in _new_conn
    conn = connection.create_connection(
  File "C:\Users\anant\anaconda3\lib\site-packages\urllib3\util\connection.py", line 72, in create_connection
    for res in socket.getaddrinfo(host, port, family, socket.SOCK_STREAM):
  File "C:\Users\anant\anaconda3\lib\socket.py", line 954, in getaddrinfo
    for res in _socket.getaddrinfo(host, port, family, type, proto, flags):
socket.gaierror: [Errno 11001] getaddrinfo failed

During handling of the above exception, another exception occurred:

Traceback (most recent call last):
  File "C:\Users\anant\anaconda3\lib\site-packages\urllib3\connectionpool.py", line 703, in urlopen
    httplib_response = self._make_request(
  File "C:\Users\anant\anaconda3\lib\site-packages\urllib3\connectionpool.py", line 386, in _make_request
    self._validate_conn(conn)
  File "C:\Users\anant\anaconda3\lib\site-packages\urllib3\connectionpool.py", line 1042, in _validate_conn
    conn.connect()
  File "C:\Users\anant\anaconda3\lib\site-packages\urllib3\connection.py", line 358, in connect
    self.sock = conn = self._new_conn()
  File "C:\Users\anant\anaconda3\lib\site-packages\urllib3\connection.py", line 186, in _new_conn
    raise NewConnectionError(
urllib3.exceptions.NewConnectionError: <urllib3.connection.HTTPSConnection object at 0x000001611F225310>: Failed to establish a new connection: [Errno 11001] getaddrinfo failed

During handling of the above exception, another exception occurred:

Traceback (most recent call last):
  File "C:\Users\anant\anaconda3\lib\site-packages\requests\adapters.py", line 489, in send
    resp = conn.urlopen(
  File "C:\Users\anant\anaconda3\lib\site-packages\urllib3\connectionpool.py", line 787, in urlopen
    retries = retries.increment(
  File "C:\Users\anant\anaconda3\lib\site-packages\urllib3\util\retry.py", line 592, in increment
    raise MaxRetryError(_pool, url, error or ResponseError(cause))
urllib3.exceptions.MaxRetryError: HTTPSConnectionPool(host='api.wandb.ai', port=443): Max retries exceeded with url: /graphql (Caused by NewConnectionError('<urllib3.connection.HTTPSConnection object at 0x000001611F225310>: Failed to establish a new connection: [Errno 11001] getaddrinfo failed'))

During handling of the above exception, another exception occurred:

Traceback (most recent call last):
  File "C:\Users\anant\anaconda3\lib\site-packages\wandb\sdk\lib\retry.py", line 131, in __call__
    result = self._call_fn(*args, **kwargs)
  File "C:\Users\anant\anaconda3\lib\site-packages\wandb\sdk\internal\internal_api.py", line 242, in execute
    return self.client.execute(*args, **kwargs)  # type: ignore
  File "C:\Users\anant\anaconda3\lib\site-packages\wandb\vendor\gql-0.2.0\wandb_gql\client.py", line 52, in execute
    result = self._get_result(document, *args, **kwargs)
  File "C:\Users\anant\anaconda3\lib\site-packages\wandb\vendor\gql-0.2.0\wandb_gql\client.py", line 60, in _get_result
    return self.transport.execute(document, *args, **kwargs)
  File "C:\Users\anant\anaconda3\lib\site-packages\wandb\vendor\gql-0.2.0\wandb_gql\transport\requests.py", line 38, in execute
    request = requests.post(self.url, **post_args)
  File "C:\Users\anant\anaconda3\lib\site-packages\requests\api.py", line 115, in post
    return request("post", url, data=data, json=json, **kwargs)
  File "C:\Users\anant\anaconda3\lib\site-packages\requests\api.py", line 59, in request
    return session.request(method=method, url=url, **kwargs)
  File "C:\Users\anant\anaconda3\lib\site-packages\requests\sessions.py", line 587, in request
    resp = self.send(prep, **send_kwargs)
  File "C:\Users\anant\anaconda3\lib\site-packages\requests\sessions.py", line 701, in send
    r = adapter.send(request, **kwargs)
  File "C:\Users\anant\anaconda3\lib\site-packages\requests\adapters.py", line 565, in send
    raise ConnectionError(e, request=request)
requests.exceptions.ConnectionError: HTTPSConnectionPool(host='api.wandb.ai', port=443): Max retries exceeded with url: /graphql (Caused by NewConnectionError('<urllib3.connection.HTTPSConnection object at 0x000001611F225310>: Failed to establish a new connection: [Errno 11001] getaddrinfo failed'))
2023-03-04 09:33:12,151 INFO    Thread-432:16248 [wandb_run.py:_finish():1854] finishing run ananthu2014/CS6910_DL_ASS1/n8ym820q
2023-03-04 09:33:12,151 INFO    Thread-432:16248 [jupyter.py:save_history():449] not saving jupyter history
2023-03-04 09:33:12,151 INFO    Thread-432:16248 [jupyter.py:save_ipynb():379] not saving jupyter notebook
2023-03-04 09:33:12,151 INFO    Thread-432:16248 [wandb_init.py:_jupyter_teardown():420] cleaning up jupyter logic
2023-03-04 09:33:12,151 INFO    Thread-432:16248 [wandb_run.py:_atexit_cleanup():2083] got exitcode: 0
2023-03-04 09:33:12,151 INFO    Thread-432:16248 [wandb_run.py:_restore():2066] restore
2023-03-04 09:33:12,151 INFO    Thread-432:16248 [wandb_run.py:_restore():2072] restore done
2023-03-04 09:33:20,090 INFO    Thread-432:16248 [wandb_run.py:_footer_history_summary_info():3442] rendering history
2023-03-04 09:33:20,090 INFO    Thread-432:16248 [wandb_run.py:_footer_history_summary_info():3474] rendering summary
2023-03-04 09:33:20,106 INFO    Thread-432:16248 [wandb_run.py:_footer_sync_info():3398] logging synced files
